WARNING: Could not find any nv files on this host!
Traceback (most recent call last):
  File "/ext3/miniconda3/lib/python3.9/site-packages/xarray/backends/file_manager.py", line 201, in _acquire_with_cache_info
    file = self._cache[self._key]
  File "/ext3/miniconda3/lib/python3.9/site-packages/xarray/backends/lru_cache.py", line 55, in __getitem__
    value = self._cache[key]
KeyError: [<class 'h5netcdf.core.File'>, ('/scratch/ab10313/pleiades/05_argentina_smooth_smooth/3d_data/ds_T.nc',), 'r', (('decode_vlen_strings', True), ('invalid_netcdf', None))]

During handling of the above exception, another exception occurred:

Traceback (most recent call last):
  File "/home/ab10313/submeso_ML/preprocess/05_argentina_smooth/cospectrum.py", line 23, in <module>
    ds_T = xr.open_dataset(PATH_3d+'ds_T.nc',engine="h5netcdf")
  File "/ext3/miniconda3/lib/python3.9/site-packages/xarray/backends/api.py", line 531, in open_dataset
    backend_ds = backend.open_dataset(
  File "/ext3/miniconda3/lib/python3.9/site-packages/xarray/backends/h5netcdf_.py", line 389, in open_dataset
    store = H5NetCDFStore.open(
  File "/ext3/miniconda3/lib/python3.9/site-packages/xarray/backends/h5netcdf_.py", line 181, in open
    return cls(manager, group=group, mode=mode, lock=lock, autoclose=autoclose)
  File "/ext3/miniconda3/lib/python3.9/site-packages/xarray/backends/h5netcdf_.py", line 132, in __init__
    self._filename = find_root_and_group(self.ds)[0].filename
  File "/ext3/miniconda3/lib/python3.9/site-packages/xarray/backends/h5netcdf_.py", line 192, in ds
    return self._acquire()
  File "/ext3/miniconda3/lib/python3.9/site-packages/xarray/backends/h5netcdf_.py", line 184, in _acquire
    with self._manager.acquire_context(needs_lock) as root:
  File "/ext3/miniconda3/lib/python3.9/contextlib.py", line 119, in __enter__
    return next(self.gen)
  File "/ext3/miniconda3/lib/python3.9/site-packages/xarray/backends/file_manager.py", line 189, in acquire_context
    file, cached = self._acquire_with_cache_info(needs_lock)
  File "/ext3/miniconda3/lib/python3.9/site-packages/xarray/backends/file_manager.py", line 207, in _acquire_with_cache_info
    file = self._opener(*self._args, **kwargs)
  File "/ext3/miniconda3/lib/python3.9/site-packages/h5netcdf/core.py", line 973, in __init__
    self._h5file = self._h5py.File(
  File "/ext3/miniconda3/lib/python3.9/site-packages/h5py/_hl/files.py", line 533, in __init__
    fid = make_fid(name, mode, userblock_size, fapl, fcpl, swmr=swmr)
  File "/ext3/miniconda3/lib/python3.9/site-packages/h5py/_hl/files.py", line 226, in make_fid
    fid = h5f.open(name, flags, fapl=fapl)
  File "h5py/_objects.pyx", line 54, in h5py._objects.with_phil.wrapper
  File "h5py/_objects.pyx", line 55, in h5py._objects.with_phil.wrapper
  File "h5py/h5f.pyx", line 106, in h5py.h5f.open
FileNotFoundError: [Errno 2] Unable to open file (unable to open file: name = '/scratch/ab10313/pleiades/05_argentina_smooth_smooth/3d_data/ds_T.nc', errno = 2, error message = 'No such file or directory', flags = 0, o_flags = 0)
