WARNING: Could not find any nv files on this host!
T,S,UV,W FULL DATASETS FROM LLC4320
CASE south_pacific/
2022-12-18 23:20:00.299096
path already exsits...
path already exsits...
LOAD DATASET: ds_UV
2022-12-18 23:20:00.301921
SELECET AREA ON U GRID
2022-12-18 23:21:59.879234
ds_U:SELECT
2022-12-18 23:21:59.900478
/ext3/miniconda3/lib/python3.9/site-packages/xarray/core/indexing.py:1380: PerformanceWarning: Slicing is producing a large chunk. To accept the large
chunk and silence this warning, set the option
    >>> with dask.config.set(**{'array.slicing.split_large_chunks': False}):
    ...     array[indexer]

To avoid creating the large chunks, set the option
    >>> with dask.config.set(**{'array.slicing.split_large_chunks': True}):
    ...     array[indexer]
  value = value[(slice(None),) * axis + (subkey,)]
ds_U:SAVE NETCDF
2022-12-18 23:38:38.416476
Traceback (most recent call last):
  File "/ext3/miniconda3/lib/python3.9/site-packages/fsspec/implementations/http.py", line 391, in _info
    await _file_info(
  File "/ext3/miniconda3/lib/python3.9/site-packages/fsspec/implementations/http.py", line 772, in _file_info
    r.raise_for_status()
  File "/home/ab10313/.local/lib/python3.9/site-packages/aiohttp/client_reqrep.py", line 1004, in raise_for_status
    raise ClientResponseError(
aiohttp.client_exceptions.ClientResponseError: 503, message='Service Unavailable', url=URL('https://data.nas.nasa.gov/ecco/download_data.php?file=/eccodata/llc_4320/compressed/0000957312/V.0000957312.data.shrunk')

The above exception was the direct cause of the following exception:

Traceback (most recent call last):
  File "/home/ab10313/submeso_ML/preprocess/south_pacific/llc4320_south_pacific.py", line 111, in <module>
    ds_U.to_netcdf(PATH+'raw_data/ds_U.nc',engine='h5netcdf')
  File "/ext3/miniconda3/lib/python3.9/site-packages/xarray/core/dataarray.py", line 3217, in to_netcdf
    return to_netcdf(  # type: ignore  # mypy cannot resolve the overloads:(
  File "/ext3/miniconda3/lib/python3.9/site-packages/xarray/backends/api.py", line 1219, in to_netcdf
    writes = writer.sync(compute=compute)
  File "/ext3/miniconda3/lib/python3.9/site-packages/xarray/backends/common.py", line 168, in sync
    delayed_store = da.store(
  File "/ext3/miniconda3/lib/python3.9/site-packages/dask/array/core.py", line 1163, in store
    compute_as_if_collection(Array, store_dsk, map_keys, **kwargs)
  File "/ext3/miniconda3/lib/python3.9/site-packages/dask/base.py", line 317, in compute_as_if_collection
    return schedule(dsk2, keys, **kwargs)
  File "/ext3/miniconda3/lib/python3.9/site-packages/dask/threaded.py", line 81, in get
    results = get_async(
  File "/ext3/miniconda3/lib/python3.9/site-packages/dask/local.py", line 506, in get_async
    raise_exception(exc, tb)
  File "/ext3/miniconda3/lib/python3.9/site-packages/dask/local.py", line 314, in reraise
    raise exc
  File "/ext3/miniconda3/lib/python3.9/site-packages/dask/local.py", line 219, in execute_task
    result = _execute_task(task, data)
  File "/ext3/miniconda3/lib/python3.9/site-packages/dask/core.py", line 119, in _execute_task
    return func(*(_execute_task(a, cache) for a in args))
  File "/ext3/miniconda3/lib/python3.9/site-packages/dask/core.py", line 119, in <genexpr>
    return func(*(_execute_task(a, cache) for a in args))
  File "/ext3/miniconda3/lib/python3.9/site-packages/dask/core.py", line 119, in _execute_task
    return func(*(_execute_task(a, cache) for a in args))
  File "/ext3/miniconda3/lib/python3.9/site-packages/dask/core.py", line 119, in <genexpr>
    return func(*(_execute_task(a, cache) for a in args))
  File "/ext3/miniconda3/lib/python3.9/site-packages/dask/core.py", line 119, in _execute_task
    return func(*(_execute_task(a, cache) for a in args))
  File "/ext3/miniconda3/lib/python3.9/site-packages/dask/core.py", line 119, in <genexpr>
    return func(*(_execute_task(a, cache) for a in args))
  File "/ext3/miniconda3/lib/python3.9/site-packages/dask/core.py", line 119, in _execute_task
    return func(*(_execute_task(a, cache) for a in args))
  File "/ext3/miniconda3/lib/python3.9/site-packages/dask/core.py", line 119, in <genexpr>
    return func(*(_execute_task(a, cache) for a in args))
  File "/ext3/miniconda3/lib/python3.9/site-packages/dask/core.py", line 119, in _execute_task
    return func(*(_execute_task(a, cache) for a in args))
  File "/ext3/miniconda3/lib/python3.9/site-packages/dask/core.py", line 119, in <genexpr>
    return func(*(_execute_task(a, cache) for a in args))
  File "/ext3/miniconda3/lib/python3.9/site-packages/dask/core.py", line 119, in _execute_task
    return func(*(_execute_task(a, cache) for a in args))
  File "/ext3/miniconda3/lib/python3.9/site-packages/dask/core.py", line 119, in <genexpr>
    return func(*(_execute_task(a, cache) for a in args))
  File "/ext3/miniconda3/lib/python3.9/site-packages/dask/core.py", line 119, in _execute_task
    return func(*(_execute_task(a, cache) for a in args))
  File "/ext3/miniconda3/lib/python3.9/site-packages/dask/core.py", line 119, in <genexpr>
    return func(*(_execute_task(a, cache) for a in args))
  File "/ext3/miniconda3/lib/python3.9/site-packages/dask/core.py", line 119, in _execute_task
    return func(*(_execute_task(a, cache) for a in args))
  File "/home/ab10313/.local/lib/python3.9/site-packages/xmitgcm/llcreader/llcmodel.py", line 459, in _get_facet_chunk
    file = fs.open(path)
  File "/ext3/miniconda3/lib/python3.9/site-packages/fsspec/spec.py", line 1034, in open
    f = self._open(
  File "/ext3/miniconda3/lib/python3.9/site-packages/fsspec/implementations/http.py", line 340, in _open
    size = size or self.info(path, **kwargs)["size"]
  File "/ext3/miniconda3/lib/python3.9/site-packages/fsspec/asyn.py", line 111, in wrapper
    return sync(self.loop, func, *args, **kwargs)
  File "/ext3/miniconda3/lib/python3.9/site-packages/fsspec/asyn.py", line 96, in sync
    raise return_result
  File "/ext3/miniconda3/lib/python3.9/site-packages/fsspec/asyn.py", line 53, in _runner
    result[0] = await coro
  File "/ext3/miniconda3/lib/python3.9/site-packages/fsspec/implementations/http.py", line 404, in _info
    raise FileNotFoundError(url) from exc
FileNotFoundError: https://data.nas.nasa.gov/ecco/download_data.php?file=/eccodata/llc_4320/compressed/0000957312/V.0000957312.data.shrunk
